Workbook

Sheet Assumptions
A1: Self-Serve Dependency Score - assumptions (recommended method)
A3: Weights
A4: Broker reliance weight | B4: 0.5
A5: App activity weight | B5: 0.3
A6: Offer activity weight | B6: 0.2
A8: Gate: broker reliance % at or below this = not broker-led (score 0) | B8: 20
A9: High Dependency: score >= | B9: 70
A10: Medium Dependency: score >= | B10: 40
A12: Broker reliance bands (pct)
A13: <= this -> 0 | B13: 20
A14: < this -> 25 | B14: 40
A15: < this -> 50 | B15: 60
A16: < this -> 75 (else 100) | B16: 80
A18: App active days bands
A19: > this -> 0 | B19: 30
A20: >= this -> 25 | B20: 20
A21: >= this -> 50 | B21: 10
A22: >= this -> 75 (else 100) | B22: 5
A24: Make-an-offer bands
A25: >= this -> 0 | B25: 5
A26: >= this -> 25 | B26: 3
A27: equals this -> 50 | B27: 2
A28: equals this -> 75 (0 offers -> 100) | B28: 1
A30: Low-confidence flag: orders_6m <= | B30: 2
A32: Source: weights and initial bands supplied by Zain (case-study brief). Changes vs brief: broker 0-band is <=20% (was <20%) and the broker gate; both explained in the report.
A33: Commercial lens (stage 2)
A34: Higher-value threshold: 6m GMV >= (£) | B34: 2000
A35: Key-account threshold: 6m GMV >= (£) | B35: 10000
A36: Momentum band: Growing if H2 >= H1 x (1 + this); Declining if H2 < H1 x (1 - this); else Stable | B36: 0.2
A38: Segmentation (stage 3)
A39: Phase 1 cohort rule: minimum orders_6m | B39: 3
A40: Phase 1 cohort rule: minimum self_serve_orders | B40: 2
A41: Broker % inconsistency flag: gap vs order counts greater than (pts) | B41: 10
A42: Critical data-quality blocker (Phase 1 cohort) = account_status "Duplicate". All other flags are warnings and never change a segment.
A43: February completeness is UNCONFIRMED. H2 (Dec-Feb) momentum assumes February is a full month.
A45: Stage 3.1 guardrails (context flags - never change a segment)
A46: Borderline momentum: H2 vs H1 within this many points of +20% or -20% | B46: 0.05
A47: Lifecycle: New Customer if tenure_months <= (only for H2 Active / No H1 GMV accounts) | B47: 6
A48: Lapse context: One-Off / Insufficient History if orders_6m <= | B48: 2
A49: Lapse context: One-Off / Insufficient History if months with GMV <= | B49: 1
...

Sheet Execution Queue
A1: Execution Queue - RUN001 baseline (300 accounts). Generated by fleek_engine; drafts are NOT sent. Sorted by priority, value tier, GMV.
A3: account_id | B3: attention_priority | C3: value_tier | D3: gmv_total_6m | E3: action_segment | F3: primary_nba | G3: nba_reason_code | H3: execution_status | I3: action_state | J3: owner_role | K3: named_owner_required | L3: notify_am_before_send | M3: playbook_id | N3: recommended_channel | O3: first_action | P3: follow_up_days | Q3: success_condition | R3: stop_condition | S3: escalation_condition | T3: guardrail_codes | U3: draft_status | V3: message_template_id | W3: draft_customer_message | X3: internal_task_brief | Y3: secondary_test | Z3: secondary_test_arm | AA3: secondary_test_draft | AB3: nurture_subcontext | AC3: recent_activity_status | AD3: lifecycle_context | AE3: rising_tail_watchlist | AF3: phase1_rollout_status | AG3: buyer_cadence | AH3: migration_progress_status | AI3: next_rerun_behaviour | AJ3: change_type | AK3: change_flags | AL3: generated_action
A4: ACC-005 | B4: P0 | C4: Key | D4: 24555 | E4: 2. Protect / Retain First | F4: Retention Conversation | G4: DECLINING_KEY_CORE | H4: HOLD — Critical Data Issue | I4: On Hold | J4: Portfolio Lead | K4: =FALSE() -> FALSE | L4: =FALSE() -> FALSE | M4: PB01_RETENTION | N4: Personal email from AM, then call | O4: Portfolio Lead resolves the Duplicate status; no contact until cleared. | P4: 7 | Q4: Root cause logged and next-90-day GMV back to at least the Sep-Nov (H1) level, or the decline arrested. | R4: Customer confirms a planned pause/seasonal gap (log cadence), or no response after 2 attempts (escalate). | S4: No response after 2 attempts, or Key account with further decline -> Portfolio Lead. | T4: CRITICAL_DATA_BLOCKER | U4: Withheld: account on HOLD (critical data issue) | X4: WHY NOW: Commercially important, broker-led spend is falling. WHAT WE KNOW: - Key, Broker-Reliant, Account Managed; £24,555 6m GMV; Retailer, United Kingdom; tenure 41 months. - Momentum: Declining (Sep-Nov £17,529 -> Dec-Feb £7,025); Recently Active (last GMV month: February); 14 orders over 5 month(s). - Dependency: Medium (broker reliance 50%; 7 AM-placed / 7 self-serve orders). - Engagement: 10 product views, 8 app days, 1 offer(s), 100 Fleek chats, 0 video requests; basket Mixed. - Warnings: CRITICAL_DATA_BLOCKER. WHAT TO DO: Resolve the Duplicate status (find/merge the matching record, confirm GMV is not double-counted) before any contact. Underlying action once cleared: Retention Conversation. WHAT NOT TO DO: No outbound communication while on HOLD. SUCCESS: Root cause logged and next-90-day GMV back to at least the Sep-Nov (H1) level, or the decline arrested. | AC4: Recently Active | AD4: Existing Customer | AE4: =FALSE() -> FALSE | AF4: Not Eligible | AG4: Regular | AH4: N/A | AI4: Stay in playbook while momentum is Declining; exit when momentum is Stable/Growing for a full run; if the account lapses, NBA moves to Verify/Win-Back. | AJ4: BASELINE | AK4: BASELINE | AL4: 5b28ca9bd14c
A5: ACC-002 | B5: P1 | C5: Key | D5: 70650 | E5: 3. Win-Back / Verify | F5: Verify Demand / Win-Back | G5: LAPSED_THIN_HISTORY | H5: Ready — Human | I5: Draft Ready | J5: Account Manager | K5: =FALSE() -> FALSE | L5: =FALSE() -> FALSE | M5: PB02_VERIFY_WINBACK | N5: Personal email from AM, then call | O5: Send cadence check-in (verify, don't assume churn). | P5: 14 | Q5: Cadence recorded and account reclassified, or a new order within 90 days (60 days for recent-inactivity checks). | R5: Customer confirms infrequent/seasonal buying (set a reminder for their window) or confirms churn (log reason). | S5: Key account with no response after 2 attempts -> Portfolio Lead. | T5: MATERIAL_BROKER_INCONSISTENCY; LOW_CONFIDENCE | U5: Draft ready (not sent) | V5: VERIFY_CADENCE | W5: Hi {first_name}, Thanks for your previous orders with Fleek. I wanted to check how you usually plan your stock buying (seasonal, project by project, or ongoing) so we can get in touch at the right moments rather than too often. Happy to talk on a quick call, or just reply here with what works for you. Best, {sender_name} | X5: WHY NOW: Apparent lapse rests on 1-2 orders or one buying month; cadence is unknown. WHAT WE KNOW: - Key, Broker-Reliant, Account Managed; £70,650 6m GMV; Reseller, United States; tenure 10 months. - Momentum: Lapsed; No Meaningful History (last GMV month: October); 2 orders over 2 month(s). - Dependency: High (broker reliance 70%; 1 AM-placed / 1 self-serve orders). - Engagement: 6 product views, 2 app days, 2 offer(s), 12 Fleek chats, 0 video requests; basket Handpick-only. - Warnings: MATERIAL_BROKER_INCONSISTENCY; LOW_CONFIDENCE. WHAT TO DO: Do not assume churn. Verify expected purchase frequency first, then set the next contact window. WHAT NOT TO DO: Do not treat as churn or run a discount-led win-back. SUCCESS: Cadence recorded and account reclassified, or a new order within 90 days (60 days for recent-inactivity checks). | AC5: No Meaningful History | AD5: Existing Customer | AE5: =FALSE() -> FALSE | AF5: Not Eligible | AG5: Lumpy | AH5: N/A | AI5: If an order appears, the account re-segments automatically; if confirmed seasonal, suppress re-contact until the stated window. | AJ5: BASELINE | AK5: BASELINE | AL5: ad531f2937d6
A6: ACC-008 | B6: P1 | C6: Key | D6: 19265 | E6: 2. Protect / Retain First | F6: Retention Conversation | G6: DECLINING_KEY_CORE | H6: Ready — Human | I6: Draft Ready | J6: Account Manager | K6: =FALSE() -> FALSE | L6: =FALSE() -> FALSE | M6: PB01_RETENTION | N6: Personal email from AM, then call | O6: Read brief; send outreach to book a review call. | P6: 7 | Q6: Root cause logged and next-90-day GMV back to at least the Sep-Nov (H1) level, or the decline arrested. | R6: Customer confirms a planned pause/seasonal gap (log cadence), or no response after 2 attempts (escalate). | S6: No response after 2 attempts, or Key account with further decline -> Portfolio Lead. | T6: H2_SINGLE_MONTH_SPIKE | U6: Draft ready (not sent) | V6: RET_AM | W6: Hi {first_name}, I'd like to set up a short call to review how sourcing through Fleek is working for you at the moment and what you're planning to buy over the next few months. It will help me make sure the stock I source for you (bundles and handpicked stock) is the right fit. Would sometime later this week or early next week suit you? Best, {sender_name} | X6: WHY NOW: Commercially important, broker-led spend is falling. WHAT WE KNOW: - Key, Broker-Reliant, Account Managed; £19,265 6m GMV; Retailer, Sweden; tenure 15 months. - Momentum: Declining (Sep-Nov £12,458 -> Dec-Feb £6,808); Recently Active (last GMV month: February); 16 orders over 5 month(s). - Dependency: High (broker reliance 84%; 13 AM-placed / 3 self-serve orders). - Engagement: 13 product views, 4 app days, 0 offer(s), 29 Fleek chats, 1 video requests; basket Mixed. - Warnings: H2_SINGLE_MONTH_SPIKE. WHAT TO DO: Book a conversation. Explore stock availability, price, assortment fit, buying cadence, competitor/offline wholesaler use and operational friction. Agree a recovery plan. WHAT NOT TO DO: Do not reduce AM support or push migration; do not suggest the customer is at fault; do not propose chat/video/feature usage as the fix. SUCCESS: Root cause logged and next-90-day GMV back to at least the Sep-Nov (H1) level, or the decline arrested. | AC6: Recently Active | AD6: Existing Customer | AE6: =FALSE() -> FALSE | AF6: Not Eligible | AG6: Regular | AH6: N/A | AI6: Stay in playbook while momentum is Declining; exit when momentum is Stable/Growing for a full run; if the account lapses, NBA moves to Verify/Win-Back. | AJ6: BASELINE | AK6: BASELINE | AL6: bbf41110e504
A7: ACC-009 | B7: P1 | C7: Key | D7: 18652 | E7: 2. Protect / Retain First | F7: Retention Conversation | G7: DECLINING_KEY_CORE | H7: Ready — Human | I7: Draft Ready | J7: Account Manager | K7: =FALSE() -> FALSE | L7: =FALSE() -> FALSE | M7: PB01_RETENTION | N7: Personal email from AM, then call | O7: Read brief; send outreach to book a review call. | P7: 7 | Q7: Root cause logged and next-90-day GMV back to at least the Sep-Nov (H1) level, or the decline arrested. | R7: Customer confirms a planned pause/seasonal gap (log cadence), or no response after 2 attempts (escalate). | S7: No response after 2 attempts, or Key account with further decline -> Portfolio Lead. | U7: Draft ready (not sent) | V7: RET_AM | W7: Hi {first_name}, I'd like to set up a short call to review how sourcing through Fleek is working for you at the moment and what you're planning to buy over the next few months. It will help me make sure the stock I source for you (bundles and handpicked stock) is the right fit. Would sometime later this week or early next week suit you? Best, {sender_name} | X7: WHY NOW: Commercially important, broker-led spend is falling. WHAT WE KNOW: - Key, Broker-Reliant, Account Managed; £18,652 6m GMV; Reseller, United Kingdom; tenure 8 months. - Momentum: Declining (Sep-Nov £12,807 -> Dec-Feb £5,845); Recently Active (last GMV month: February); 35 orders over 6 month(s). - Dependency: High (broker reliance 68%; 24 AM-placed / 11 self-serve orders). - Engagement: 2 product views, 1 app days, 1 offer(s), 30 Fleek chats, 0 video requests; basket Mixed. WHAT TO DO: Book a conversation. Explore stock availability, price, assortment fit, buying cadence, competitor/offline wholesaler use and operational friction. Agree a recovery plan. WHAT NOT TO DO: Do not reduce AM support or push migration; do not suggest the customer is at fault; do not propose chat/video/feature usage as the fix. SUCCESS: Root cause logged and next-90-day GMV back to at least the Sep-Nov (H1) level, or the decline arrested. | AC7: Recently Active | AD7: Existing Customer | AE7: =FALSE() -> FALSE | AF7: Not Eligible | AG7: Regular | AH7: N/A | AI7: Stay in playbook while momentum is Declining; exit when momentum is Stable/Growing for a full run; if the account lapses, NBA moves to Verify/Win-Back. | AJ7: BASELINE | AK7: BASELINE | AL7: 14b26d9cbee4
A8: ACC-010 | B8: P1 | C8: Key | D8: 17026 | E8: 2. Protect / Retain First | F8: Retention Conversation | G8: DECLINING_KEY_CORE | H8: Ready — Human | I8: Draft Ready | J8: Account Manager | K8: =FALSE() -> FALSE | L8: =FALSE() -> FALSE | M8: PB01_RETENTION | N8: Personal email from AM, then call | O8: Read brief; send outreach to book a review call. | P8: 7 | Q8: Root cause logged and next-90-day GMV back to at least the Sep-Nov (H1) level, or the decline arrested. | R8: Customer confirms a planned pause/seasonal gap (log cadence), or no response after 2 attempts (escalate). | S8: No response after 2 attempts, or Key account with further decline -> Portfolio Lead. | U8: Draft ready (not sent) | V8: RET_AM | W8: Hi {first_name}, I'd like to set up a short call to review how sourcing through Fleek is working for you at the moment and what you're planning to buy over the next few months. It will help me make sure the stock I source for you (handpicked stock) is the right fit. Would sometime later this week or early next week suit you? Best, {sender_name} | X8: WHY NOW: Commercially important, broker-led spend is falling. WHAT WE KNOW: - Key, Broker-Reliant, Account Managed; £17,026 6m GMV; Reseller, Portugal; tenure 10 months. - Momentum: Declining (Sep-Nov £11,150 -> Dec-Feb £5,876); Recently Active (last GMV month: February); 13 orders over 6 month(s). - Dependency: High (broker reliance 69%; 9 AM-placed / 4 self-serve orders). - Engagement: 1 product views, 1 app days, 0 offer(s), 40 Fleek chats, 0 video requests; basket Handpick-only. WHAT TO DO: Book a conversation. Explore stock availability, price, assortment fit, buying cadence, competitor/offline wholesaler use and operational friction. Agree a recovery plan. WHAT NOT TO DO: Do not reduce AM support or push migration; do not suggest the customer is at fault; do not propose chat/video/feature usage as the fix. SUCCESS: Root cause logged and next-90-day GMV back to at least the Sep-Nov (H1) level, or the decline arrested. | AC8: Recently Active | AD8: Existing Customer | AE8: =FALSE() -> FALSE | AF8: Not Eligible | AG8: Regular | AH8: N/A | AI8: Stay in playbook while momentum is Declining; exit when momentum is Stable/Growing for a full run; if the account lapses, NBA moves to Verify/Win-Back. | AJ8: BASELINE | AK8: BASELINE | AL8: 4966e1678608
A9: ACC-013 | B9: P1 | C9: Key | D9: 14315 | E9: 2. Protect / Retain First | F9: Retention Conversation | G9: DECLINING_KEY_CORE | H9: Ready — Human | I9: Draft Ready | J9: Account Manager | K9: =FALSE() -> FALSE | L9: =FALSE() -> FALSE | M9: PB01_RETENTION | N9: Personal email from AM, then call | O9: Read brief; send outreach to book a review call. | P9: 7 | Q9: Root cause logged and next-90-day GMV back to at least the Sep-Nov (H1) level, or the decline arrested. | R9: Customer confirms a planned pause/seasonal gap (log cadence), or no response after 2 attempts (escalate). | S9: No response after 2 attempts, or Key account with further decline -> Portfolio Lead. | U9: Draft ready (not sent) | V9: RET_AM | W9: Hi {first_name}, I'd like to set up a short call to review how sourcing through Fleek is working for you at the moment and what you're planning to buy over the next few months. It will help me make sure the stock I source for you (bundles and handpicked stock) is the right fit. Would sometime later this week or early next week suit you? Best, {sender_name} | X9: WHY NOW: Commercially important, broker-led spend is falling. WHAT WE KNOW: - Key, Broker-Reliant, Account Managed; £14,315 6m GMV; Reseller, United Kingdom; tenure 17 months. - Momentum: Declining (Sep-Nov £9,966 -> Dec-Feb £4,350); Recently Active (last GMV month: February); 21 orders over 5 month(s). - Dependency: Medium (broker reliance 59%; 12 AM-placed / 9 self-serve orders). - Engagement: 5 product views, 8 app days, 1 offer(s), 36 Fleek chats, 0 video requests; basket Mixed. WHAT TO DO: Book a conversation. Explore stock availability, price, assortment fit, buying cadence, competitor/offline wholesaler use and operational friction. Agree a recovery plan. WHAT NOT TO DO: Do not reduce AM support or push migration; do not suggest the customer is at fault; do not propose chat/video/feature usage as the fix. SUCCESS: Root cause logged and next-90-day GMV back to at least the Sep-Nov (H1) level, or the decline arrested. | AC9: Recently Active | AD9: Existing Customer | AE9: =FALSE() -> FALSE | AF9: Not Eligible | AG9: Regular | AH9: N/A | AI9: Stay in playbook while momentum is Declining; exit when momentum is Stable/Growing for a full run; if the account lapses, NBA moves to Verify/Win-Back. | AJ9: BASELINE | AK9: BASELINE | AL9: d5ca9688e26f
A10: ACC-211 | B10: P1 | C10: Key | D10: 13412 | E10: 8. Retention / Reactivation | F10: Retention Conversation | G10: ENGAGED_BUT_SHRINKING | H10: Ready — Human | I10: Draft Ready | J10: Customer Success / Growth | K10: =TRUE() -> TRUE | L10: =FALSE() -> FALSE | M10: PB01_RETENTION | N10: Personal email, then call | O10: Read brief; send outreach to book a call. | P10: 7 | Q10: Root cause logged and next-90-day GMV back to at least the Sep-Nov (H1) level, or the decline arrested. | R10: Customer confirms a planned pause/seasonal gap (log cadence), or no response after 2 attempts (escalate). | S10: No response after 2 attempts, or Key account with further decline -> Portfolio Lead. | T10: H2_SINGLE_MONTH_SPIKE | U10: Draft ready (not sent) | V10: RET_CS | W10: Hi {first_name}, I'm part of the Fleek team and wanted to hear how the platform is working for your buying at the moment. Is anything making it harder to find or secure the stock you need? I'd value a short call to understand what would be most useful for you over the coming months. Would a quick call this week work? Best, {sender_name} | X10: WHY NOW: Heavily self-serving account whose spend is falling; product adoption is not the issue. WHAT WE KNOW: - Key, Self-Serve, Self Serve; £13,412 6m GMV; Reseller, France; tenure 5 months. - Momentum: Declining (Sep-Nov £9,034 -> Dec-Feb £4,378); Recent Inactivity (last GMV month: December); 15 orders over 3 month(s). - Dependency: Low (broker reliance 0%; 0 AM-placed / 15 self-serve orders). - Engagement: 6665 product views, 100 app days, 71 offer(s), 18 Fleek chats, 0 video requests; basket Mixed. - Warnings: H2_SINGLE_MONTH_SPIKE. WHAT TO DO: Book a conversation. The customer already uses the product heavily: explore stock availability, price, offer outcomes and competitor use. WHAT NOT TO DO: Do not send more product nudges - engagement is not the problem. SUCCESS: Root cause logged and next-90-day GMV back to at least the Sep-Nov (H1) level, or the decline arrested. | AC10: Recent Inactivity | AD10: Existing Customer | AE10: =FALSE() -> FALSE | AF10: Not Eligible | AG10: Regular | AH10: N/A | AI10: Stay in playbook while momentum is Declining; exit when momentum is Stable/Growing for a full run; if the account lapses, NBA moves to Verify/Win-Back. | AJ10: BASELINE | AK10: BASELINE | AL10: 1147923b913d
A11: ACC-014 | B11: P1 | C11: Key | D11: 11721 | E11: 2. Protect / Retain First | F11: Retention Conversation | G11: DECLINING_KEY_CORE | H11: Ready — Human | I11: Draft Ready | J11: Account Manager | K11: =FALSE() -> FALSE | L11: =FALSE() -> FALSE | M11: PB01_RETENTION | N11: Personal email from AM, then call | O11: Read brief; send outreach to book a review call. | P11: 7 | Q11: Root cause logged and next-90-day GMV back to at least the Sep-Nov (H1) level, or the decline arrested. | R11: Customer confirms a planned pause/seasonal gap (log cadence), or no response after 2 attempts (escalate). | S11: No response after 2 attempts, or Key account with further decline -> Portfolio Lead. | U11: Draft ready (not sent) | V11: RET_AM | W11: Hi {first_name}, I'd like to set up a short call to review how sourcing through Fleek is working for you at the moment and what you're planning to buy over the next few months. It will help me make sure the stock I source for you (bundles and handpicked stock) is the right fit. Would sometime later this week or early next week suit you? Best, {sender_name} | X11: WHY NOW: Commercially important, broker-led spend is falling. WHAT WE KNOW: - Key, Broker-Reliant, Account Managed; £11,721 6m GMV; Reseller, United States; tenure 8 months. - Momentum: Declining (Sep-Nov £7,060 -> Dec-Feb £4,661); Recently Active (last GMV month: February); 27 orders over 6 month(s). - Dependency: High (broker reliance 81%; 22 AM-placed / 5 self-serve orders). - Engagement: 1 product views, 5 app days, 0 offer(s), 64 Fleek chats, 36 video requests; basket Mixed. WHAT TO DO: Book a conversation. Explore stock availability, price, assortment fit, buying cadence, competitor/offline wholesaler use and operational friction. Agree a recovery plan. WHAT NOT TO DO: Do not reduce AM support or push migration; do not suggest the customer is at fault; do not propose chat/video/feature usage as the fix. SUCCESS: Root cause logged and next-90-day GMV back to at least the Sep-Nov (H1) level, or the decline arrested. | AC11: Recently Active | AD11: Existing Customer | AE11: =FALSE() -> FALSE | AF11: Not Eligible | AG11: Regular | AH11: N/A | AI11: Stay in playbook while momentum is Declining; exit when momentum is Stable/Growing for a full run; if the account lapses, NBA moves to Verify/Win-Back. | AJ11: BASELINE | AK11: BASELINE | AL11: 3541cedf4075
A12: ACC-015 | B12: P1 | C12: Key | D12: 11481 | E12: 3. Win-Back / Verify | F12: Verify Demand / Win-Back | G12: LAPSED_ESTABLISHED | H12: Ready — Human | I12: Draft Ready | J12: Account Manager | K12: =FALSE() -> FALSE | L12: =FALSE() -> FALSE | M12: PB02_VERIFY_WINBACK | N12: Personal email from AM, then call | O12: Send win-back check-in. | P12: 14 | Q12: Cadence recorded and account reclassified, or a new order within 90 days (60 days for recent-inactivity checks). | R12: Customer confirms infrequent/seasonal buying (set a reminder for their window) or confirms churn (log reason). | S12: Key account with no response after 2 attempts -> Portfolio Lead. | U12: Draft ready (not sent) | V12: WINBACK | W12: Hi {first_name}, It's been a little while since we last caught up, so I wanted to check in on your buying plans for the coming months. If you're sourcing bundles and handpicked stock again soon, I'd be glad to talk through what you're looking for and how we can help. Would a quick call be useful? Best, {sender_name} | X12: WHY NOW: Established buyer with a repeat pattern has had no GMV since November or earlier. WHAT WE KNOW: - Key, Broker-Reliant, Account Managed; £11,481 6m GMV; Reseller, United Kingdom; tenure 13 months. - Momentum: Lapsed; Recent Inactivity (last GMV month: November); 8 orders over 3 month(s). - Dependency: High (broker reliance 64%; 5 AM-placed / 3 self-serve orders). - Engagement: 5 product views, 6 app days, 1 offer(s), 96 Fleek chats, 0 video requests; basket Mixed. WHAT TO DO: Win-back conversation about upcoming buying needs and what would bring them back. WHAT NOT TO DO: Do not say 'you churned' or 'you've stopped buying'. SUCCESS: Cadence recorded and account reclassified, or a new order within 90 days (60 days for recent-inactivity checks). | AC12: Recent Inactivity | AD12: Existing Customer | AE12: =FALSE() -> FALSE | AF12: Not Eligible | AG12: Regular | AH12: N/A | AI12: If an order appears, the account re-segments automatically; if confirmed seasonal, suppress re-contact until the stated window. | AJ12: BASELINE | AK12: BASELINE | AL12: 2285c67f93e3
A13: ACC-017 | B13: P1 | C13: Key | D13: 10950 | E13: 2. Protect / Retain First | F13: Retention Conversation | G13: DECLINING_KEY_CORE | H13: Ready — Human | I13: Draft Ready | J13: Account Manager | K13: =FALSE() -> FALSE | L13: =FALSE() -> FALSE | M13: PB01_RETENTION | N13: Personal email from AM, then call | O13: Read brief; send outreach to book a review call. | P13: 7 | Q13: Root cause logged and next-90-day GMV back to at least the Sep-Nov (H1) level, or the decline arrested. | R13: Customer confirms a planned pause/seasonal gap (log cadence), or no response after 2 attempts (escalate). | S13: No response after 2 attempts, or Key account with further decline -> Portfolio Lead. | T13: H2_SINGLE_MONTH_SPIKE | U13: Draft ready (not sent) | V13: RET_AM | W13: Hi {first_name}, I'd like to set up a short call to review how sourcing through Fleek is working for you at the moment and what you're planning to buy over the next few months. It will help me make sure the stock I source for you (bundles and handpicked stock) is the right fit. Would sometime later this week or early next week suit you? Best, {sender_name} | X13: WHY NOW: Commercially important, broker-led spend is falling. WHAT WE KNOW: - Key, Broker-Reliant, Account Managed; £10,950 6m GMV; Reseller, United Kingdom; tenure 18 months. - Momentum: Declining (Sep-Nov £7,711 -> Dec-Feb £3,238); Recently Active (last GMV month: February); 37 orders over 5 month(s). - Dependency: High (broker reliance 78%; 29 AM-placed / 8 self-serve orders). - Engagement: 2 product views, 4 app days, 1 offer(s), 55 Fleek chats, 1 video requests; basket Mixed. - Warnings: H2_SINGLE_MONTH_SPIKE. WHAT TO DO: Book a conversation. Explore stock availability, price, assortment fit, buying cadence, competitor/offline wholesaler use and operational friction. Agree a recovery plan. WHAT NOT TO DO: Do not reduce AM support or push migration; do not suggest the customer is at fault; do not propose chat/video/feature usage as the fix. SUCCESS: Root cause logged and next-90-day GMV back to at least the Sep-Nov (H1) level, or the decline arrested. | AC13: Recently Active | AD13: Existing Customer | AE13: =FALSE() -> FALSE | AF13: Not Eligible | AG13: Regular | AH13: N/A | AI13: Stay in playbook while momentum is Declining; exit when momentum is Stable/Growing for a full run; if the account lapses, NBA moves to Verify/Win-Back. | AJ13: BASELINE | AK13: BASELINE | AL13: 5cb38fc6a985
A14: ACC-018 | B14: P1 | C14: Core | D14: 8613 | E14: 2. Protect / Retain First | F14: Retention Conversation | G14: DECLINING_KEY_CORE | H14: Ready — Human | I14: Draft Ready | J14: Account Manager | K14: =FALSE() -> FALSE | L14: =FALSE() -> FALSE | M14: PB01_RETENTION | N14: Personal email from AM, then call | O14: Read brief; send outreach to book a review call. | P14: 7 | Q14: Root cause logged and next-90-day GMV back to at least the Sep-Nov (H1) level, or the decline arrested. | R14: Customer confirms a planned pause/seasonal gap (log cadence), or no response after 2 attempts (escalate). | S14: No response after 2 attempts, or Key account with further decline -> Portfolio Lead. | T14: FEB_SENSITIVE; NO_FEB_GMV (Feb unconfirmed) | U14: Draft ready (not sent) | V14: RET_AM | W14: Hi {first_name}, I'd like to set up a short call to review how sourcing through Fleek is working for you at the moment and what you're planning to buy over the next few months. It will help me make sure the stock I source for you (bundles) is the right fit. Would sometime later this week or early next week suit you? Best, {sender_name} | X14: WHY NOW: Commercially important, broker-led spend is falling. WHAT WE KNOW: - Core, Broker-Reliant, Account Managed; £8,613 6m GMV; Reseller, United Kingdom; tenure 10 months. - Momentum: Declining (Sep-Nov £5,605 -> Dec-Feb £3,010); Recently Active (last GMV month: January); 11 orders over 5 month(s). - Dependency: High (broker reliance 74%; 8 AM-placed / 3 self-serve orders). - Engagement: 10 product views, 3 app days, 0 offer(s), 1 Fleek chats, 0 video requests; basket Bundle-only. - Warnings: FEB_SENSITIVE; NO_FEB_GMV (Feb unconfirmed). WHAT TO DO: Book a conversation. Explore stock availability, price, assortment fit, buying cadence, competitor/offline wholesaler use and operational friction. Agree a recovery plan. WHAT NOT TO DO: Do not reduce AM support or push migration; do not suggest the customer is at fault; do not propose chat/video/feature usage as the fix. SUCCESS: Root cause logged and next-90-day GMV back to at least the Sep-Nov (H1) level, or the decline arrested. | AC14: Recently Active | AD14: Existing Customer | AE14: =FALSE() -> FALSE | AF14: Not Eligible | AG14: Regular | AH14: N/A | AI14: Stay in playbook while momentum is Declining; exit when momentum is Stable/Growing for a full run; if the account lapses, NBA moves to Verify/Win-Back. | AJ14: BASELINE | AK14: BASELINE | AL14: b301fe425ce1
A15: ACC-021 | B15: P1 | C15: Core | D15: 6199 | E15: 2. Protect / Retain First | F15: Retention Conversation | G15: DECLINING_KEY_CORE | H15: Ready — Human | I15: Draft Ready | J15: Account Manager | K15: =FALSE() -> FALSE | L15: =FALSE() -> FALSE | M15: PB01_RETENTION | N15: Personal email from AM, then call | O15: Read brief; send outreach to book a review call. | P15: 7 | Q15: Root cause logged and next-90-day GMV back to at least the Sep-Nov (H1) level, or the decline arrested. | R15: Customer confirms a planned pause/seasonal gap (log cadence), or no response after 2 attempts (escalate). | S15: No response after 2 attempts, or Key account with further decline -> Portfolio Lead. | U15: Draft ready (not sent) | V15: RET_AM | W15: Hi {first_name}, I'd like to set up a short call to review how sourcing through Fleek is working for you at the moment and what you're planning to buy over the next few months. It will help me make sure the stock I source for you (bundles and handpicked stock) is the right fit. Would sometime later this week or early next week suit you? Best, {sender_name} | X15: WHY NOW: Commercially important, broker-led spend is falling. WHAT WE KNOW: - Core, Broker-Reliant, Account Managed; £6,199 6m GMV; Reseller, France; tenure 7 months. - Momentum: Declining (Sep-Nov £3,866 -> Dec-Feb £2,332); Recently Active (last GMV month: February); 19 orders over 6 month(s). - Dependency: High (broker reliance 64%; 12 AM-placed / 7 self-serve orders). - Engagement: 2 product views, 6 app days, 1 offer(s), 19 Fleek chats, 13 video requests; basket Mixed. WHAT TO DO: Book a conversation. Explore stock availability, price, assortment fit, buying cadence, competitor/offline wholesaler use and operational friction. Agree a recovery plan. WHAT NOT TO DO: Do not reduce AM support or push migration; do not suggest the customer is at fault; do not propose chat/video/feature usage as the fix. SUCCESS: Root cause logged and next-90-day GMV back to at least the Sep-Nov (H1) level, or the decline arrested. | AC15: Recently Active | AD15: Existing Customer | AE15: =FALSE() -> FALSE | AF15: Not Eligible | AG15: Regular | AH15: N/A | AI15: Stay in playbook while momentum is Declining; exit when momentum is Stable/Growing for a full run; if the account lapses, NBA moves to Verify/Win-Back. | AJ15: BASELINE | AK15: BASELINE | AL15: 71752711fe5b
A16: ACC-022 | B16: P1 | C16: Core | D16: 6140 | E16: 2. Protect / Retain First | F16: Retention Conversation | G16: DECLINING_KEY_CORE | H16: Ready — Human | I16: Draft Ready | J16: Account Manager | K16: =FALSE() -> FALSE | L16: =FALSE() -> FALSE | M16: PB01_RETENTION | N16: Personal email from AM, then call | O16: Read brief; send outreach to book a review call. | P16: 7 | Q16: Root cause logged and next-90-day GMV back to at least the Sep-Nov (H1) level, or the decline arrested. | R16: Customer confirms a planned pause/seasonal gap (log cadence), or no response after 2 attempts (escalate). | S16: No response after 2 attempts, or Key account with further decline -> Portfolio Lead. | T16: H2_SINGLE_MONTH_SPIKE | U16: Draft ready (not sent) | V16: RET_AM | W16: Hi {first_name}, I'd like to set up a short call to review how sourcing through Fleek is working for you at the moment and what you're planning to buy over the next few months. It will help me make sure the stock I source for you (bundles) is the right fit. Would sometime later this week or early next week suit you? Best, {sender_name} | X16: WHY NOW: Commercially important, broker-led spend is falling. WHAT WE KNOW: - Core, Broker-Reliant, Account Managed; £6,140 6m GMV; Reseller, United States; tenure 21 months. - Momentum: Declining (Sep-Nov £4,539 -> Dec-Feb £1,601); Recent Inactivity (last GMV month: December); 7 orders over 3 month(s). - Dependency: Medium (broker reliance 49%; 3 AM-placed / 4 self-serve orders). - Engagement: 12 product views, 4 app days, 2 offer(s), 33 Fleek chats, 2 video requests; basket Bundle-only. - Warnings: H2_SINGLE_MONTH_SPIKE. WHAT TO DO: Book a conversation. Explore stock availability, price, assortment fit, buying cadence, competitor/offline wholesaler use and operational friction. Agree a recovery plan. WHAT NOT TO DO: Do not reduce AM support or push migration; do not suggest the customer is at fault; do not propose chat/video/feature usage as the fix. SUCCESS: Root cause logged and next-90-day GMV back to at least the Sep-Nov (H1) level, or the decline arrested. | AC16: Recent Inactivity | AD16: Existing Customer | AE16: =FALSE() -> FALSE | AF16: Not Eligible | AG16: Regular | AH16: N/A | AI16: Stay in playbook while momentum is Declining; exit when momentum is Stable/Growing for a full run; if the account lapses, NBA moves to Verify/Win-Back. | AJ16: BASELINE | AK16: BASELINE | AL16: 8f37f6a06496
A17: ACC-023 | B17: P1 | C17: Core | D17: 5727 | E17: 2. Protect / Retain First | F17: Retention Conversation | G17: DECLINING_KEY_CORE | H17: Ready — Human | I17: Draft Ready | J17: Account Manager | K17: =FALSE() -> FALSE | L17: =FALSE() -> FALSE | M17: PB01_RETENTION | N17: Personal email from AM, then call | O17: Read brief; send outreach to book a review call. | P17: 7 | Q17: Root cause logged and next-90-day GMV back to at least the Sep-Nov (H1) level, or the decline arrested. | R17: Customer confirms a planned pause/seasonal gap (log cadence), or no response after 2 attempts (escalate). | S17: No response after 2 attempts, or Key account with further decline -> Portfolio Lead. | T17: FEB_SENSITIVE; H2_SINGLE_MONTH_SPIKE | U17: Draft ready (not sent) | V17: RET_AM | W17: Hi {first_name}, I'd like to set up a short call to review how sourcing through Fleek is working for you at the moment and what you're planning to buy over the next few months. It will help me make sure the stock I source for you (handpicked stock) is the right fit. Would sometime later this week or early next week suit you? Best, {sender_name} | X17: WHY NOW: Commercially important, broker-led spend is falling. WHAT WE KNOW: - Core, Broker-Reliant, Account Managed; £5,727 6m GMV; Reseller, France; tenure 43 months. - Momentum: Declining (Sep-Nov £4,800 -> Dec-Feb £927); Recently Active (last GMV month: February); 4 orders over 4 month(s). - Dependency: High (broker reliance 64%; 3 AM-placed / 1 self-serve orders). - Engagement: 10 product views, 0 app days, 1 offer(s), 9 Fleek chats, 0 video requests; basket Handpick-only. - Warnings: FEB_SENSITIVE; H2_SINGLE_MONTH_SPIKE. WHAT TO DO: Book a conversation. Explore stock availability, price, assortment fit, buying cadence, competitor/offline wholesaler use and operational friction. Agree a recovery plan. WHAT NOT TO DO: Do not reduce AM support or push migration; do not suggest the customer is at fault; do not propose chat/video/feature usage as the fix. SUCCESS: Root cause logged and next-90-day GMV back to at least the Sep-Nov (H1) level, or the decline arrested. | AC17: Recently Active | AD17: Existing Customer | AE17: =FALSE() -> FALSE | AF17: Not Eligible | AG17: Lumpy | AH17: N/A | AI17: Stay in playbook while momentum is Declining; exit when momentum is Stable/Growing for a full run; if the account lapses, NBA moves to Verify/Win-Back. | AJ17: BASELINE | AK17: BASELINE | AL17: 2808d52199a5
A18: ACC-026 | B18: P1 | C18: Core | D18: 4772 | E18: 3. Win-Back / Verify | F18: Verify Demand / Win-Back | G18: LAPSED_THIN_HISTORY | H18: Ready — Human | I18: Draft Ready | J18: Account Manager | K18: =FALSE() -> FALSE | L18: =FALSE() -> FALSE | M18: PB02_VERIFY_WINBACK | N18: Personal email from AM, then call | O18: Send cadence check-in (verify, don't assume churn). | P18: 14 | Q18: Cadence recorded and account reclassified, or a new order within 90 days (60 days for recent-inactivity checks). | R18: Customer confirms infrequent/seasonal buying (set a reminder for their window) or confirms churn (log reason). | S18: Key account with no response after 2 attempts -> Portfolio Lead. | T18: LOW_CONFIDENCE | U18: Draft ready (not sent) | V18: VERIFY_CADENCE | W18: Hi {first_name}, Thanks for your previous orders with Fleek. I wanted to check how you usually plan your stock buying (seasonal, project by project, or ongoing) so we can get in touch at the right moments rather than too often. Happy to talk on a quick call, or just reply here with what works for you. Best, {sender_name} | X18: WHY NOW: Apparent lapse rests on 1-2 orders or one buying month; cadence is unknown. WHAT WE KNOW: - Core, Broker-Reliant, Account Managed; £4,772 6m GMV; Reseller, Germany; tenure 9 months. - Momentum: Lapsed; No Meaningful History (last GMV month: November); 2 orders over 2 month(s). - Dependency: High (broker reliance 82%; 2 AM-placed / 0 self-serve orders). - Engagement: 0 product views, 1 app days, 2 offer(s), 6 Fleek chats, 0 video requests; basket Bundle-only. - Warnings: LOW_CONFIDENCE. WHAT TO DO: Do not assume churn. Verify expected purchase frequency first, then set the next contact window. WHAT NOT TO DO: Do not treat as churn or run a discount-led win-back. SUCCESS: Cadence recorded and account reclassified, or a new order within 90 days (60 days for recent-inactivity checks). | AC18: No Meaningful History | AD18: Existing Customer | AE18: =FALSE() -> FALSE | AF18: Not Eligible | AG18: Lumpy | AH18: N/A | AI18: If an order appears, the account re-segments automatically; if confirmed seasonal, suppress re-contact until the stated window. | AJ18: BASELINE | AK18: BASELINE | AL18: beae7abebe16
A19: ACC-028 | B19: P1 | C19: Core | D19: 4639 | E19: 2. Protect / Retain First | F19: Retention Conversation | G19: DECLINING_KEY_CORE | H19: Ready — Human | I19: Draft Ready | J19: Account Manager | K19: =FALSE() -> FALSE | L19: =FALSE() -> FALSE | M19: PB01_RETENTION | N19: Personal email from AM, then call | O19: Read brief; send outreach to book a review call. | P19: 7 | Q19: Root cause logged and next-90-day GMV back to at least the Sep-Nov (H1) level, or the decline arrested. | R19: Customer confirms a planned pause/seasonal gap (log cadence), or no response after 2 attempts (escalate). | S19: No response after 2 attempts, or Key account with further decline -> Portfolio Lead. | T19: H2_SINGLE_MONTH_SPIKE; NO_FEB_GMV (Feb unconfirmed) | U19: Draft ready (not sent) | V19: RET_AM | W19: Hi {first_name}, I'd like to set up a short call to review how sourcing through Fleek is working for you at the moment and what you're planning to buy over the next few months. It will help me make sure the stock I source for you (handpicked stock) is the right fit. Would sometime later this week or early next week suit you? Best, {sender_name} | X19: WHY NOW: Commercially important, broker-led spend is falling. WHAT WE KNOW: - Core, Broker-Reliant, Account Managed; £4,639 6m GMV; Reseller, Netherlands; tenure 11 months. - Momentum: Declining (Sep-Nov £3,271 -> Dec-Feb £1,368); Recently Active (last GMV month: January); 7 orders over 4 month(s). - Dependency: High (broker reliance 48%; 3 AM-placed / 4 self-serve orders). - Engagement: 8 product views, 4 app days, 1 offer(s), 35 Fleek chats, 0 video requests; basket Handpick-only. - Warnings: H2_SINGLE_MONTH_SPIKE; NO_FEB_GMV (Feb unconfirmed). WHAT TO DO: Book a conversation. Explore stock availability, price, assortment fit, buying cadence, competitor/offline wholesaler use and operational friction. Agree a recovery plan. WHAT NOT TO DO: Do not reduce AM support or push migration; do not suggest the customer is at fault; do not propose chat/video/feature usage as the fix. SUCCESS: Root cause logged and next-90-day GMV back to at least the Sep-Nov (H1) level, or the decline arrested. | AC19: Recently Active | AD19: Existing Customer | AE19: =FALSE() -> FALSE | AF19: Not Eligible | AG19: Regular | AH19: N/A | AI19: Stay in playbook while momentum is Declining; exit when momentum is Stable/Growing for a full run; if the account lapses, NBA moves to Verify/Win-Back. | AJ19: BASELINE | AK19: BASELINE | AL19: f91bbd0fb68a
A20: ACC-214 | B20: P1 | C20: Core | D20: 4632 | E20: 8. Retention / Reactivation | F20: Retention Conversation | G20: ENGAGED_BUT_SHRINKING | H20: Ready — Human | I20: Draft Ready | J20: Customer Success / Growth | K20: =TRUE() -> TRUE | L20: =FALSE() -> FALSE | M20: PB01_RETENTION | N20: Personal email, then call | O20: Read brief; send outreach to book a call. | P20: 7 | Q20: Root cause logged and next-90-day GMV back to at least the Sep-Nov (H1) level, or the decline arrested. | R20: Customer confirms a planned pause/seasonal gap (log cadence), or no response after 2 attempts (escalate). | S20: No response after 2 attempts, or Key account with further decline -> Portfolio Lead. | T20: H2_SINGLE_MONTH_SPIKE; NO_FEB_GMV (Feb unconfirmed) | U20: Draft ready (not sent) | V20: RET_CS | W20: Hi {first_name}, I'm part of the Fleek team and wanted to hear how the platform is working for your buying at the moment. Is anything making it harder to find or secure the stock you need? I'd value a short call to understand what would be most useful for you over the coming months. Would a quick call this week work? Best, {sender_name} | X20: WHY NOW: Heavily self-serving account whose spend is falling; product adoption is not the issue. WHAT WE KNOW: - Core, Self-Serve, Self Serve; £4,632 6m GMV; Reseller, United Kingdom; tenure 5 months. - Momentum: Declining (Sep-Nov £4,516 -> Dec-Feb £116); Recently Active (last GMV month: January); 12 orders over 3 month(s). - Dependency: Low (broker reliance 0%; 0 AM-placed / 12 self-serve orders). - Engagement: 665 product views, 74 app days, 53 offer(s), 70 Fleek chats, 1 video requests; basket Mixed. - Warnings: H2_SINGLE_MONTH_SPIKE; NO_FEB_GMV (Feb unconfirmed). WHAT TO DO: Book a conversation. The customer already uses the product heavily: explore stock availability, price, offer outcomes and competitor use. WHAT NOT TO DO: Do not send more product nudges - engagement is not the problem. SUCCESS: Root cause logged and next-90-day GMV back to at least the Sep-Nov (H1) level, or the decline arrested. | AC20: Recently Active | AD20: Existing Customer | AE20: =FALSE() -> FALSE | AF20: Not Eligible | AG20: Regular | AH20: N/A | AI20: Stay in playbook while momentum is Declining; exit when momentum is Stable/Growing for a full run; if the account lapses, NBA moves to Verify/Win-Back. | AJ20: BASELINE | AK20: BASELINE | AL20: 85018850706f
A21: ACC-032 | B21: P1 | C21: Core | D21: 4179 | E21: 3. Win-Back / Verify | F21: Verify Demand / Win-Back | G21: LAPSED_THIN_HISTORY | H21: Ready — Human | I21: Draft Ready | J21: Account Manager | K21: =FALSE() -> FALSE | L21: =FALSE() -> FALSE | M21: PB02_VERIFY_WINBACK | N21: Personal email from AM, then call | O21: Send cadence check-in (verify, don't assume churn). | P21: 14 | Q21: Cadence recorded and account reclassified, or a new order within 90 days (60 days for recent-inactivity checks). | R21: Customer confirms infrequent/seasonal buying (set a reminder for their window) or confirms churn (log reason). | S21: Key account with no response after 2 attempts -> Portfolio Lead. | T21: LOW_CONFIDENCE | U21: Draft ready (not sent) | V21: VERIFY_CADENCE | W21: Hi {first_name}, Thanks for your previous orders with Fleek. I wanted to check how you usually plan your stock buying (seasonal, project by project, or ongoing) so we can get in touch at the right moments rather than too often. Happy to talk on a quick call, or just reply here with what works for you. Best, {sender_name} | X21: WHY NOW: Apparent lapse rests on 1-2 orders or one buying month; cadence is unknown. WHAT WE KNOW: - Core, Broker-Reliant, Account Managed; £4,179 6m GMV; Reseller, France; tenure 12 months. - Momentum: Lapsed; No Meaningful History (last GMV month: November); 2 orders over 2 month(s). - Dependency: High (broker reliance 80%; 2 AM-placed / 0 self-serve orders). - Engagement: 10 product views, 1 app days, 1 offer(s), 64 Fleek chats, 0 video requests; basket Handpick-only. - Warnings: LOW_CONFIDENCE. WHAT TO DO: Do not assume churn. Verify expected purchase frequency first, then set the next contact window. WHAT NOT TO DO: Do not treat as churn or run a discount-led win-back. SUCCESS: Cadence recorded and account reclassified, or a new order within 90 days (60 days for recent-inactivity checks). | AC21: No Meaningful History | AD21: Existing Customer | AE21: =FALSE() -> FALSE | AF21: Not Eligible | AG21: Lumpy | AH21: N/A | AI21: If an order appears, the account re-segments automatically; if confirmed seasonal, suppress re-contact until the stated window. | AJ21: BASELINE | AK21: BASELINE | AL21: 8480fbee4c85
A22: ACC-215 | B22: P1 | C22: Core | D22: 3907 | E22: 8. Retention / Reactivation | F22: Verify Demand / Win-Back | G22: LAPSED_THIN_HISTORY | H22: Ready — Human | I22: Draft Ready | J22: Customer Success / Growth | K22: =TRUE() -> TRUE | L22: =FALSE() -> FALSE | M22: PB02_VERIFY_WINBACK | N22: Personal email, then call | O22: Send cadence check-in (verify, don't assume churn). | P22: 14 | Q22: Cadence recorded and account reclassified, or a new order within 90 days (60 days for recent-inactivity checks). | R22: Customer confirms infrequent/seasonal buying (set a reminder for their window) or confirms churn (log reason). | S22: Key account with no response after 2 attempts -> Portfolio Lead. | T22: LOW_CONFIDENCE | U22: Draft ready (not sent) | V22: VERIFY_CADENCE | W22: Hi {first_name}, Thanks for your previous orders with Fleek. I wanted to check how you usually plan your stock buying (seasonal, project by project, or ongoing) so we can get in touch at the right moments rather than too often. Happy to talk on a quick call, or just reply here with what works for you. Best, {sender_name} | X22: WHY NOW: Apparent lapse rests on 1-2 orders or one buying month; cadence is unknown. WHAT WE KNOW: - Core, Self-Serve, Self Serve; £3,907 6m GMV; Reseller, United States; tenure 5 months. - Momentum: Lapsed; No Meaningful History (last GMV month: October); 1 orders over 1 month(s). - Dependency: Low (broker reliance 0%; 0 AM-placed / 1 self-serve orders). - Engagement: 76 product views, 14 app days, 0 offer(s), 3 Fleek chats, 0 video requests; basket Handpick-only. - Warnings: LOW_CONFIDENCE. WHAT TO DO: Do not assume churn. Verify expected purchase frequency first, then set the next contact window. WHAT NOT TO DO: Do not treat as churn or run a discount-led win-back. SUCCESS: Cadence recorded and account reclassified, or a new order within 90 days (60 days for recent-inactivity checks). | AC22: No Meaningful History | AD22: Existing Customer | AE22: =FALSE() -> FALSE | AF22: Not Eligible | AG22: Lumpy | AH22: N/A | AI22: If an order appears, the account re-segments automatically; if confirmed seasonal, suppress re-contact until the stated window. | AJ22: BASELINE | AK22: BASELINE | AL22: 7be89ed5f41b
A23: ACC-035 | B23: P1 | C23: Core | D23: 3906 | E23: 2. Protect / Retain First | F23: Retention Conversation | G23: DECLINING_KEY_CORE | H23: Ready — Human | I23: Draft Ready | J23: Account Manager | K23: =FALSE() -> FALSE | L23: =FALSE() -> FALSE | M23: PB01_RETENTION | N23: Personal email from AM, then call | O23: Read brief; send outreach to book a review call. | P23: 7 | Q23: Root cause logged and next-90-day GMV back to at least the Sep-Nov (H1) level, or the decline arrested. | R23: Customer confirms a planned pause/seasonal gap (log cadence), or no response after 2 attempts (escalate). | S23: No response after 2 attempts, or Key account with further decline -> Portfolio Lead. | T23: MATERIAL_BROKER_INCONSISTENCY; H2_SINGLE_MONTH_SPIKE; NO_FEB_GMV (Feb unconfirmed) | U23: Draft ready (not sent) | V23: RET_AM | W23: Hi {first_name}, I'd like to set up a short call to review how sourcing through Fleek is working for you at the moment and what you're planning to buy over the next few months. It will help me make sure the stock I source for you (handpicked stock) is the right fit. Would sometime later this week or early next week suit you? Best, {sender_name} | X23: WHY NOW: Commercially important, broker-led spend is falling. WHAT WE KNOW: - Core, Broker-Reliant, Account Managed; £3,906 6m GMV; Reseller, United Kingdom; tenure 19 months. - Momentum: Declining (Sep-Nov £2,595 -> Dec-Feb £1,311); Recently Active (last GMV month: January); 5 orders over 3 month(s). - Dependency: Medium (broker reliance 55%; 3 AM-placed / 2 self-serve orders). - Engagement: 11 product views, 6 app days, 0 offer(s), 86 Fleek chats, 3 video requests; basket Handpick-only. - Warnings: MATERIAL_BROKER_INCONSISTENCY; H2_SINGLE_MONTH_SPIKE; NO_FEB_GMV (Feb unconfirmed). WHAT TO DO: Book a conversation. Explore stock availability, price, assortment fit, buying cadence, competitor/offline wholesaler use and operational friction. Agree a recovery plan. WHAT NOT TO DO: Do not reduce AM support or push migration; do not suggest the customer is at fault; do not propose chat/video/feature usage as the fix. SUCCESS: Root cause logged and next-90-day GMV back to at least the Sep-Nov (H1) level, or the decline arrested. | AC23: Recently Active | AD23: Existing Customer | AE23: =FALSE() -> FALSE | AF23: Not Eligible | AG23: Regular | AH23: N/A | AI23: Stay in playbook while momentum is Declining; exit when momentum is Stable/Growing for a full run; if the account lapses, NBA moves to Verify/Win-Back. | AJ23: BASELINE | AK23: BASELINE | AL23: 54b853a6f434
A24: ACC-037 | B24: P1 | C24: Core | D24: 3863 | E24: 2. Protect / Retain First | F24: Retention Conversation | G24: DECLINING_KEY_CORE | H24: Ready — Human | I24: Draft Ready | J24: Account Manager | K24: =FALSE() -> FALSE | L24: =FALSE() -> FALSE | M24: PB01_RETENTION | N24: Personal email from AM, then call | O24: Read brief; send outreach to book a review call. | P24: 7 | Q24: Root cause logged and next-90-day GMV back to at least the Sep-Nov (H1) level, or the decline arrested. | R24: Customer confirms a planned pause/seasonal gap (log cadence), or no response after 2 attempts (escalate). | S24: No response after 2 attempts, or Key account with further decline -> Portfolio Lead. | U24: Draft ready (not sent) | V24: RET_AM | W24: Hi {first_name}, I'd like to set up a short call to review how sourcing through Fleek is working for you at the moment and what you're planning to buy over the next few months. It will help me make sure the stock I source for you (bundles and handpicked stock) is the right fit. Would sometime later this week or early next week suit you? Best, {sender_name} | X24: WHY NOW: Commercially important, broker-led spend is falling. WHAT WE KNOW: - Core, Broker-Reliant, Account Managed; £3,863 6m GMV; Reseller, Belgium; tenure 11 months. - Momentum: Declining (Sep-Nov £2,595 -> Dec-Feb £1,267); Recently Active (last GMV month: February); 7 orders over 4 month(s). - Dependency: High (broker reliance 84%; 6 AM-placed / 1 self-serve orders). - Engagement: 8 product views, 2 app days, 1 offer(s), 55 Fleek chats, 0 video requests; basket Mixed. WHAT TO DO: Book a conversation. Explore stock availability, price, assortment fit, buying cadence, competitor/offline wholesaler use and operational friction. Agree a recovery plan. WHAT NOT TO DO: Do not reduce AM support or push migration; do not suggest the customer is at fault; do not propose chat/video/feature usage as the fix. SUCCESS: Root cause logged and next-90-day GMV back to at least the Sep-Nov (H1) level, or the decline arrested. | AC24: Recently Active | AD24: Existing Customer | AE24: =FALSE() -> FALSE | AF24: Not Eligible | AG24: Regular | AH24: N/A | AI24: Stay in playbook while momentum is Declining; exit when momentum is Stable/Growing for a full run; if the account lapses, NBA moves to Verify/Win-Back. | AJ24: BASELINE | AK24: BASELINE | AL24: f3fb6364e78b
A25: ACC-038 | B25: P1 | C25: Core | D25: 3702 | E25: 8. Retention / Reactivation | F25: Verify Demand / Win-Back | G25: LAPSED_THIN_HISTORY | H25: Ready — Human | I25: Draft Ready | J25: Account Manager | K25: =FALSE() -> FALSE | L25: =FALSE() -> FALSE | M25: PB02_VERIFY_WINBACK | N25: Personal email from AM, then call | O25: Send cadence check-in (verify, don't assume churn). | P25: 14 | Q25: Cadence recorded and account reclassified, or a new order within 90 days (60 days for recent-inactivity checks). | R25: Customer confirms infrequent/seasonal buying (set a reminder for their window) or confirms churn (log reason). | S25: Key account with no response after 2 attempts -> Portfolio Lead. | T25: LOW_CONFIDENCE | U25: Draft ready (not sent) | V25: VERIFY_CADENCE | W25: Hi {first_name}, Thanks for your previous orders with Fleek. I wanted to check how you usually plan your stock buying (seasonal, project by project, or ongoing) so we can get in touch at the right moments rather than too often. Happy to talk on a quick call, or just reply here with what works for you. Best, {sender_name} | X25: WHY NOW: Apparent lapse rests on 1-2 orders or one buying month; cadence is unknown. WHAT WE KNOW: - Core, AM-Owned / Self-Serving, Account Managed; £3,702 6m GMV; Retailer, United Kingdom; tenure 32 months. - Momentum: Lapsed; No Meaningful History (last GMV month: October); 2 orders over 2 month(s). - Dependency: Low (broker reliance 4%; 0 AM-placed / 2 self-serve orders). - Engagement: 78 product views, 16 app days, 2 offer(s), 37 Fleek chats, 0 video requests; basket Handpick-only. - Warnings: LOW_CONFIDENCE. WHAT TO DO: Do not assume churn. Verify expected purchase frequency first, then set the next contact window. WHAT NOT TO DO: Do not treat as churn or run a discount-led win-back. SUCCESS: Cadence recorded and account reclassified, or a new order within 90 days (60 days for recent-inactivity checks). | AC25: No Meaningful History | AD25: Existing Customer | AE25: =FALSE() -> FALSE | AF25: Not Eligible | AG25: Lumpy | AH25: N/A | AI25: If an order appears, the account re-segments automatically; if confirmed seasonal, suppress re-contact until the stated window. | AJ25: BASELINE | AK25: BASELINE | AL25: 172ea5e0f915
A26: ACC-040 | B26: P1 | C26: Core | D26: 3579 | E26: 2. Protect / Retain First | F26: Retention Conversation | G26: DECLINING_KEY_CORE | H26: Ready — Human | I26: Draft Ready | J26: Account Manager | K26: =FALSE() -> FALSE | L26: =FALSE() -> FALSE | M26: PB01_RETENTION | N26: Personal email from AM, then call | O26: Read brief; send outreach to book a review call. | P26: 7 | Q26: Root cause logged and next-90-day GMV back to at least the Sep-Nov (H1) level, or the decline arrested. | R26: Customer confirms a planned pause/seasonal gap (log cadence), or no response after 2 attempts (escalate). | S26: No response after 2 attempts, or Key account with further decline -> Portfolio Lead. | T26: FEB_SENSITIVE; H2_SINGLE_MONTH_SPIKE | U26: Draft ready (not sent) | V26: RET_AM | W26: Hi {first_name}, I'd like to set up a short call to review how sourcing through Fleek is working for you at the moment and what you're planning to buy over the next few months. It will help me make sure the stock I source for you (handpicked stock) is the right fit. Would sometime later this week or early next week suit you? Best, {sender_name} | X26: WHY NOW: Commercially important, broker-led spend is falling. WHAT WE KNOW: - Core, Broker-Reliant, Account Managed; £3,579 6m GMV; Reseller, United States; tenure 12 months. - Momentum: Declining (Sep-Nov £2,692 -> Dec-Feb £887); Recently Active (last GMV month: February); 6 orders over 3 month(s). - Dependency: High (broker reliance 72%; 4 AM-placed / 2 self-serve orders). - Engagement: 13 product views, 6 app days, 1 offer(s), 8 Fleek chats, 1 video requests; basket Handpick-only. - Warnings: FEB_SENSITIVE; H2_SINGLE_MONTH_SPIKE. WHAT TO DO: Book a conversation. Explore stock availability, price, assortment fit, buying cadence, competitor/offline wholesaler use and operational friction. Agree a recovery plan. WHAT NOT TO DO: Do not reduce AM support or push migration; do not suggest the customer is at fault; do not propose chat/video/feature usage as the fix. SUCCESS: Root cause logged and next-90-day GMV back to at least the Sep-Nov (H1) level, or the decline arrested. | AC26: Recently Active | AD26: Existing Customer | AE26: =FALSE() -> FALSE | AF26: Not Eligible | AG26: Regular | AH26: N/A | AI26: Stay in playbook while momentum is Declining; exit when momentum is Stable/Growing for a full run; if the account lapses, NBA moves to Verify/Win-Back. | AJ26: BASELINE | AK26: BASELINE | AL26: 923b662583c0
A27: ACC-041 | B27: P1 | C27: Core | D27: 3549 | E27: 2. Protect / Retain First | F27: Retention Conversation | G27: DECLINING_KEY_CORE | H27: Ready — Human | I27: Draft Ready | J27: Account Manager | K27: =FALSE() -> FALSE | L27: =FALSE() -> FALSE | M27: PB01_RETENTION | N27: Personal email from AM, then call | O27: Read brief; send outreach to book a review call. | P27: 7 | Q27: Root cause logged and next-90-day GMV back to at least the Sep-Nov (H1) level, or the decline arrested. | R27: Customer confirms a planned pause/seasonal gap (log cadence), or no response after 2 attempts (escalate). | S27: No response after 2 attempts, or Key account with further decline -> Portfolio Lead. | T27: MATERIAL_BROKER_INCONSISTENCY; NO_FEB_GMV (Feb unconfirmed) | U27: Draft ready (not sent) | V27: RET_AM | W27: Hi {first_name}, I'd like to set up a short call to review how sourcing through Fleek is working for you at the moment and what you're planning to buy over the next few months. It will help me make sure the stock I source for you (bundles and handpicked stock) is the right fit. Would sometime later this week or early next week suit you? Best, {sender_name} | X27: WHY NOW: Commercially important, broker-led spend is falling. WHAT WE KNOW: - Core, Broker-Reliant, Account Managed; £3,549 6m GMV; Reseller, France; tenure 28 months. - Momentum: Declining (Sep-Nov £2,505 -> Dec-Feb £1,045); Recently Active (last GMV month: January); 7 orders over 5 month(s). - Dependency: High (broker reliance 61%; 4 AM-placed / 3 self-serve orders). - Engagement: 2 product views, 6 app days, 0 offer(s), 25 Fleek chats, 0 video requests; basket Mixed. - Warnings: MATERIAL_BROKER_INCONSISTENCY; NO_FEB_GMV (Feb unconfirmed). WHAT TO DO: Book a conversation. Explore stock availability, price, assortment fit, buying cadence, competitor/offline wholesaler use and operational friction. Agree a recovery plan. WHAT NOT TO DO: Do not reduce AM support or push migration; do not suggest the customer is at fault; do not propose chat/video/feature usage as the fix. SUCCESS: Root cause logged and next-90-day GMV back to at least the Sep-Nov (H1) level, or the decline arrested. | AC27: Recently Active | AD27: Existing Customer | AE27: =FALSE() -> FALSE | AF27: Not Eligible | AG27: Regular | AH27: N/A | AI27: Stay in playbook while momentum is Declining; exit when momentum is Stable/Growing for a full run; if the account lapses, NBA moves to Verify/Win-Back. | AJ27: BASELINE | AK27: BASELINE | AL27: 664c8c477044
